---
title: Promise学习04
tags: [ES6]
---
# Promise学习04
本文章主要记录Mocha测试框架与Promise配合的情况
。
## 使用done的Promise测试
```
var assert = require('power-assert');
describe('Basic Test', function () {
    context('When Callback(high-order function)', function () {
        it('should use `done` for test', function (done) {
            setTimeout(function () {
                assert(true);
                done();
            }, 0);
        });
    });
    context('When promise object', function () {
        it('should use `done` for test?', function (done) {
            var promise = Promise.resolve(1);
            promise.then(function (value) {
                assert(value === 1);
                done();
            });
        });
    });
});
```
## 对异常Promise测试
```
 it("should use `done` for test?", function(done) {
            var promise = Promise.resolve();
            promise.then(function(value) {
                assert(false); // => throw AssertionError
                done();
            });
        });
```
错误信息如下：
```
     Error: Timeout of 2000ms exceeded. For async tests and hooks, ensure "done()" is called; if returning a Promise, ensure it resolves. (D:\Workspaces\promise\promiseTest.js)

```
上述代码抛出异常后，done并没有被执行。为了保证done一定被执行，修改代码为：
```
  it("should use `done` for test?", function(done) {
            var promise = Promise.resolve();
            promise.then(function(value) {
                throw new Error();
                done();
            }).catch(done, done);
        });
```

## mocha对Promise的支持
在对Promise进行测试的时候，不使用 done() 这样的回调风格的代码编写方式，而是返回一个promise对象。
```
var assert = require('power-assert');
describe('Promise Test', function () {
    it('should return a promise object', function () {
        var promise = Promise.resolve(1);
        return promise.then(function (value) {
            assert(value === 1);
        });
    });
});
```
上述代码主要特点：
- 删除了done
- 返回结果为Promise对象   
这样就从本质上避免了`.then(done,done)`


## 编写可控测试代码
### 可控测试定义
待测试的promise对象
1. 如果编写预期为Fulfilled状态的测试的话
- Rejected的时候要 Fail
- assertion 的结果不一致的时候要 Fail
2. 如果预期为Rejected状态的话
- 结果为Fulfilled 测试为 Fail
- assertion 的结果不一致的时候要 Fail   
综上一个测试用例应该包括下面的测试内容。
- 结果满足 Fulfilled or Rejected 之一
- 对传递给assertion的值进行检查


## helper函数
### shouldRejected函数
```
function shouldRejected(promise) {
    return {
        'catch': function(fn) {
            return promise.then(function() {
                throw new Error('Expected promise to be rejected but it was fulfilled');
            }, function(reason) {
                fn.call(promise, reason);
            });
        }
    };
}
it('should be rejected', function() {
    var promise = Promise.reject(new Error('human error'));
    return shouldRejected(promise).catch(function(error) {
        console.log(error.message === 'human error');
    });
});
```
在 shouldRejected 外部，都是类似如下、和普通的promise处理大同小异的代码。
1. 将需要测试的promise对象传递给 shouldRejected 方法
2. 在返回的对象的 catch 方法中编写进行onRejected处理的代码
3. 在onRejected里使用assertion进行判断   

在使用 shouldRejected 函数的时候，如果是 Fulfilled 被调用了的话，则会throw一个异常，测试也会失败。

### shouldFulfilled函数
```
var assert = require('power-assert');
function shouldFulfilled(promise) {
    return {
        'then': function (fn) {
            return promise.then(function (value) {
                fn.call(promise, value);
            }, function (reason) {
                throw reason;
            });
        }
    };
}
it('should be fulfilled', function () {
    var promise = Promise.resolve('value');
    return shouldFulfilled(promise).then(function (value) {
        assert(value === 'value');
    });
});
```
这和上面的 `shouldRejected-test.js` 结构基本相同，只不过返回对象的 `catch` 方法变为了 `then ，promise.then`的两个参数也调换了。
## 参考
[promise教程](http://liubin.org/promises-book/#how-to-write-promise)
